Workbook
Name W_CONDITION: Lookups!$B$17
Name CFDeficit_Flag: Lookups!$M$3
Name Default_Flag: Lookups!$M$11
Name Collateral_Flag: Lookups!$M$8
Name Income_Var_Flag: Lookups!$M$4
Name Equity_Flag: Lookups!$M$5
Name LTV_MAX_IMMOVABLE: Lookups!$B$6
Name W_CAPITAL: Lookups!$B$15
Name CASHFLOW_DEFICIT_REPAY_SHARE_MAX: Lookups!$B$4
Name LTV_MAX_MOVABLE: Lookups!$B$5
Name BUSINESS_AGE_MIN: Lookups!$B$9
Name DATA_VARIANCE_MAX: Lookups!$B$8
Name BUSINESS_LOAN_HARD_MAX_ETB: Lookups!$B$12
Name DSCR_TARGET: Lookups!$B$3
Name W_COLLATERAL: Lookups!$B$16
Name BRANCH_APPROVAL_LIMIT_ETB: Lookups!$B$11
Name STRESS_FACTOR: Lookups!$B$2
Name AGE_MAX: Lookups!$B$10
Name Branch_Limit_Flag: Lookups!$M$9
Name LTV_Flag: Lookups!$M$7
Name W_CAPACITY: Lookups!$B$14
Name W_CHARACTER: Lookups!$B$13
Name Training_Flag: Lookups!$M$6
Name Age_Flag: Lookups!$M$2
Name Loan_Max_Flag: Lookups!$M$10
Name EQUITY_MIN_RATIO: Lookups!$B$7
Name SECTOR: BL_Scorecard!$C$17

Sheet README
A1: How to use
A3: Use 'BL_Scorecard' and fill ONLY the yellow cells.
A4: Outputs: stressed DSCR, category scores, total score (1–99), risk band, flags, recommendation.
A5: Hard-stops: repayment >50% of monthly surplus => Reject; income variance >20% (if stated value ≠ verified value) => Reject; Business age < 6 months => Reject.
A6: Refer flags: Equity <10% of loan; no training; collateral shortfall; collateral uninsured; above branch limit.
A7: Score bands: 85–99 approve; 70–84 approve with conditions; 55–69 refer head office; 1–54 reject.
A8: Edit parameters in 'Lookups' if policy changes. Protection password: hmfi.

Sheet BL_Scorecard
B1: Harar MFI - Business Loan (L101) Scorecard
B2: v1 | 2026-02-11 | Score 1-99 | Yellow=input
B3: Credit Officer ID | G3: Hard Max (ETB) | H3: =BUSINESS_LOAN_HARD_MAX_ETB -> 3000000
B4: Credit Officer Name | G4: Branch Limit (ETB) | H4: =BRANCH_APPROVAL_LIMIT_ETB -> 50000
B5: 1) Applicant & Loan Request
B7: Applicant Name | E7: Applicant ID | G7: Sex (M/F)
B8: Age (years) | E8: Marital Status | G8: Primary Applicant Literacy Level
B9: Repeat Borrower? | E9: Loan Series (if repeat borrower) | G9: Prior Default with HMFI or other institutions?
B10: Branch | E10: Application Date
B11: Requested Loan Amount | E11: Monthly Installment (if extra payments)
B12: Term (months) | E12: Annual Interest Rate (%) | G12: Monthly Installment (Used) | H12: =IF(F11<>"",F11,IF(AND(C11<>"",C12<>"",F12<>""),-PMT((F12/100)/12,C12,C11),"" ))
B14: 2) Business Details
B16: Business Name | E16: Ownership Structure | G16: Site Visit Assessment | H16: 0
B17: Sector | E17: Training/Certification? | G17: Is Business Seasonal?
B18: Business Type / Description | E18: Years in Business (in months) | G18: Character References
B19: Loan Purpose | E19: Stability of Business Location (months)
B21: 3) Affordability / Monthly Cash Flow / Repayment Capacity
B23: Stated Average Monthly Revenue (ETB) | E23: Bank Statement Verified Avg Monthly Revenue (ETB)
B24: COGS / Inventory | E24: Other Monthly Income
B25: Rent | E25: Household Expenses
B26: Utilities | E26: Owner Withdrawals/Dividend Monthly Average
B27: Wages
B28: Transport
B29: Other Operating Costs (incl. taxes)
B31: Total Operating Expenses | C31: =IF(OR(C25="",C26="",C27="",C28="",C29=""),"",C25+C26+C27+C28+C29) | E31: Business Surplus (stressed) | F31: =IF(C32="","",C32*STRESS_FACTOR) | G31: Business Net Margin | H31: =IF(OR(F23="",C32=""),"",IF(F23=0,"",C32/F23))
B32: Business Surplus (unstressed) | C32: =IF(OR(F23="",C24="",C31=""),"",F23-C24-C31) | E32: Total Monthly Surplus (stressed) | F32: =IF(OR(F31="",F24="",F25="",F26=""),"",F31+F24-F25-F26)
B33: Total Monthly Surplus (unstressed) | C33: =IF(OR(C32="",F24="",F25="",F26=""),"",C32+F24-F25-F26) | E33: Stressed DSCR (stressed Surplus / Installment) | F33: =IF(OR(H12="",F32=""),"",IF(H12=0,"",F32/H12)) | G33: DSCR (Surplus / Installment) | H33: =IF(OR(H12="",C32=""),"",IF(H12=0,"",C32/H12))
B34: Repayment Share (Installment / Unstressed Surplus) | C34: =IF(OR(H12="",C33=""),"",IF(C33<=0,1,H12/C33)) | E34: Income Variance (|stated-verified| / verified) | F34: =IF(OR(C23="",F23="",F23=0),"",ABS(C23-F23)/F23)
B35: 4) Equity / Capital
B36: Total Capital | E36: Cash At Bank / Additional Savings / Equity (ETB)
B37: Equity Ratio (Total / Loan) | C37: =IF(OR(C11="",C11=0,C36="",F36=""),"",(C36+F36)/C11) | E37: Liquidity Coverage | F37: =IF(OR(F36="",C31="",C24="",H12="",F26=""),"",F36/(C24+C31+H12+F26))
B39: 5) Collateral
B40: Collateral Type | E40: Collateral Insured?
B41: Market Value (ETB)
B42: Haircut (%) | C42: =IF(C40="Movable",0.5,IF(C40="Immovable",0.3,0)) -> 0 | E42: Collateral Coverage | F42: =IF(H42="","",1/H42) | G42: LTV (Loan / Net Collateral) | H42: =IF(OR(C11="",C41="",C40=""),"",IF(C40="None",99,C11/(C41*(1-C42))))
B44: 6) Outputs (Score, Flags, Decision)
E45: Total Score (1–99) | F45: =MAX(1,MIN(99,IF(OR(C46="",C47="",C48="",C49="",C50=""),"",C46+C47+C48+C49+C50))) -> 1 | G45: Risk Band | H45: =IF(F45="","",IF(F45>=85,"Very Low Risk",IF(F45>=70,"Low Risk",IF(F45>=55,"Moderate Risk",IF(F45>=40,"High Risk","Very High Risk"))))) -> Very High Risk
B46: Character (max 30) | C46: =MIN(W_CHARACTER,IF(F17="Yes",5,0)+IF(H7="F",3,0)+IF(F18="",0,IF(F18>=36,12,IF(F18>=24,10,IF(F18>=12,6,0))))+IF(H18="Good",5,IF(H18="Average",2,0))+IF(C8>=40,2,0)+IF(F8="Married",1,0)+IF(C9="Yes",3,0)+IF(AND(C9="Yes",F9>=3),5,0)) -> 0
B47: Capacity (max 39) | C47: =MIN(W_CAPACITY,IF(F33="",0,IF(F33>=1.5,34,IF(F33>=DSCR_TARGET,28,IF(F33>=1.1,18,IF(F33>=0.9,8,0)))))) -> 0 | E47: Flags (Triggered) | F47: =TEXTJOIN(CHAR(10),TRUE,IF(Age_Flag,"REJECT: Business less than 6 months",""),IF(CFDeficit_Flag,"REJECT: Cash flow deficit (repayment >50% of surplus)",""),IF(Income_Var_Flag,"REJECT: Data inconsistency (>20% variance)",""),IF(Default_Flag,"REJECT: Prior default with HMFI",""),IF(Loan_Max_Flag,"REJECT: Above hard max loan amount",""),IF(Equity_Flag,"REFER: Equity <10% of loan",""),IF(Training_Flag,"REFER: No training/certification",""),IF(LTV_Flag,"REFER: Collateral shortfall (LTV too high)",""),IF(Collateral_Flag,"REFER: Collateral not insured",""),IF(Branch_Limit_Flag,"REFER: Above branch approval limit",""),IF(C40="None","REJECT: No Collateral","")) -> REJECT: Business less than 6 months
B48: Capital (max 10) | C48: =MIN(W_CAPITAL,IF(C37="",0,IF(C37>=0.2,15,IF(C37>=0.15,12,IF(C37>=EQUITY_MIN_RATIO,8,IF(C37>=0.05,3,0))))) ) -> 0
...

Sheet Lookups
A1: Parameter | B1: Value | C1: Notes | E1: Sector | F1: Stress Factor | H1: Total Score | I1: Risk Band | J1: Decision Recommendations | L1: FLAG | M1: VALUE | N1: OUTCOME IF "TRUE"
A2: STRESS_FACTOR | B2: {=XLOOKUP(BL_Scorecard!C17, E2:E6, F2:F6,"")} | C2: Apply to business surplus for stressed DSCR. | E2: Trade | F2: 0.85 | H2: 85+ | I2: Very Low Risk | J2: Approve | L2: Business Age | M2: =OR(BL_Scorecard!F18="",BL_Scorecard!F18<BUSINESS_AGE_MIN) -> TRUE | N2: DECISION: Reject
A3: DSCR_TARGET | B3: 1.3 | C3: Target DSCR (stressed). | E3: Service | F3: 0.8 | H3: 70-84 | I3: Low Risk | J3: Approve With Conditions | L3: Cash Flow Deficit and/or repayment share | M3: =IF(OR(BL_Scorecard!C33="",BL_Scorecard!H12=""),FALSE,IF(OR(BL_Scorecard!C33<=0,BL_Scorecard!C34>CASHFLOW_DEFICIT_REPAY_SHARE_MAX),TRUE,FALSE)) -> FALSE | N3: DECISION: Reject
A4: CASHFLOW_DEFICIT_REPAY_SHARE_MAX | B4: 0.5 | C4: Reject if installment >50% of (unstressed) surplus. | E4: Manufacturing | F4: 0.7 | H4: 55-69 | I4: Moderate Risk | J4: Refer Head Office | L4: Income Variance | M4: =IF(BL_Scorecard!F34="",FALSE,IF(BL_Scorecard!F34>DATA_VARIANCE_MAX,TRUE,FALSE)) -> FALSE | N4: DECISION: Reject
A5: LTV_MAX_MOVABLE | B5: 1.25 | C5: Flag if LTV >125% (movable). | E5: Agriculture | F5: 0.6 | H5: 40-54 | I5: High Risk | J5: Reject | L5: Equity Min Ratio | M5: =IF(BL_Scorecard!C37="",FALSE,IF(BL_Scorecard!C37<EQUITY_MIN_RATIO,TRUE,FALSE)) -> FALSE | N5: FLAG: Refer
A6: LTV_MAX_IMMOVABLE | B6: 1.1 | C6: Flag if LTV >110% (immovable). | E6: Other | F6: 0.55 | H6: 1-39 | I6: Very High Risk | J6: Reject | L6: Training Certification | M6: =IF(BL_Scorecard!F17="",FALSE,IF(BL_Scorecard!F17="No",TRUE,FALSE)) -> FALSE | N6: FLAG: Refer
A7: EQUITY_MIN_RATIO | B7: 0.1 | C7: Refer if equity <10% of loan. | L7: LTV | M7: =IF(BL_Scorecard!H42="",FALSE,IF(OR(AND(BL_Scorecard!C40="Movable",BL_Scorecard!H42>LTV_MAX_MOVABLE),AND(BL_Scorecard!C40="Immovable",BL_Scorecard!H42>LTV_MAX_IMMOVABLE)),TRUE,FALSE)) -> FALSE | N7: FLAG: Refer
A8: INCOME_VARIANCE_MAX | B8: 0.2 | C8: Reject if stated vs verified income variance >20%. | L8: Collateral & Insurance | M8: =IF(OR(BL_Scorecard!C40="",BL_Scorecard!F40=""),FALSE,IF(OR(BL_Scorecard!F40="No",BL_Scorecard!C40="None"),TRUE,FALSE)) -> FALSE | N8: DECISION: Reject
A9: BUSINESS_AGE_MIN | B9: 6 | C9: Business age lower bound (months) | L9: Branch Approval Limit | M9: =IF(OR(BL_Scorecard!C11=""),FALSE,IF(BL_Scorecard!C11>BRANCH_APPROVAL_LIMIT_ETB,TRUE,FALSE)) -> FALSE | N9: FLAG: Refer
A10: AGE_MAX | B10: 99 | C10: Borrower age upper bound. | L10: Hard Max Amount | M10: =IF(OR(BL_Scorecard!C11=""),FALSE,IF(BL_Scorecard!C11>BUSINESS_LOAN_HARD_MAX_ETB,TRUE,FALSE)) -> FALSE | N10: DECISION: Reject
A11: BRANCH_APPROVAL_LIMIT_ETB | B11: 50000 | C11: Branch-level approval ceiling. | L11: Prior Default Flag | M11: =IF(BL_Scorecard!H9="",FALSE,IF(BL_Scorecard!H9="Yes",TRUE,FALSE)) -> FALSE | N11: DECISION: Reject
A12: BUSINESS_LOAN_HARD_MAX_ETB | B12: 3000000 | C12: Single borrower maximum ≤ 1% of total capital
A13: WEIGHT_CHARACTER | B13: 30 | C13: Max points. (not percentage)
A14: WEIGHT_CAPACITY | B14: 39 | C14: Max points.
A15: WEIGHT_CAPITAL | B15: 10 | C15: Max points.
A16: WEIGHT_COLLATERAL | B16: 10 | C16: Max points.
A17: WEIGHT_CONDITION | B17: 10 | C17: Max points.
